Workbook

Sheet Action Required
A1: Booked Date | B1: PO Number | C1: Channel | D1: Store Code | E1: AWB | F1: Tracking Status | G1: Latest Status | H1: Current Location | I1: EDD | J1: Appointment Date & Time | K1: Appointment ID | L1: PO PDF | M1: Invoice Url
A2: 46122 | B2: 6769710037985 | C2: Blinkit | D2: Hyderabad H3 - Feeder Warehouse | E2: 302627602 | F2: delivered | G2: Shipment Delivered | H2: Hyderabad_Temp6_L (Telangana) | I2: 46125 | J2: 46132.312 | K2: 945030195474 | L2: =HYPERLINK("https://drive.google.com/file/d/17HWpy7LvhJ03IZaPvjqYAB6yRQxNRh6o/view?usp=drivesdk", "302627602_Purchase Order") -> 302627602_Purchase Order | M2: =HYPERLINK("https://zohosecurepay.in/books/brainlyticsolutionsprivatelim2/secure?CInvoiceID=2-4dcca1fc8e91862eb3395e1b54b2e0d59c02a7500dd23fe6a64403c286be8a0e1793ef4a6595a22961593cafdbd828c494d9500e95014150086d0182747ec7f033861748a7bfa36d ", "302627602_Invoice") -> 302627602_Invoice
A3: 46187 | B3: 49990010033230 | C3: Blinkit | D3: Bengaluru B5 - Feeder Warehouse | E3: 94916022291101 | F3: rto | G3: RTO DELIVERED | H3: N/A | I3: N/A | J3: 46188.312 | K3: 146269768630 | L3: =HYPERLINK("https://drive.google.com/file/d/1fwfavdOfUOQA5ZofQsbRwBVq8GJT6uJG/view?usp=drivesdk", "94916022291101_Purchase Order") -> 94916022291101_Purchase Order | M3: =HYPERLINK("https://zohosecurepay.in/books/brainlyticsolutionsprivatelim2/secure?CInvoiceID=2-4dcca1fc8e91862e2da637b78cee2ed90f79de414f899e678651e7b33d7aaf0bb042d3ffcaabeeee61593cafdbd828c494d9500e95014150f60683d11d31aab84f1ecdf8c617d10b ", "94916022291101_Invoice") -> 94916022291101_Invoice
A4: 46187 | B4: 48287510027442 | C4: Blinkit | D4: Kolkata K6 Feeder | E4: 94916022241076 | F4: in transit | G4: InTransit | H4: CCU/PC1 - Kolkata | I4: N/A | J4: 46188.312 | K4: 259044262365 | L4: =HYPERLINK("https://drive.google.com/file/d/1XBh1pR38APQYDUGytiI3GGkZ3MnLaheU/view?usp=drivesdk", "94916022241076_Purchase Order") -> 94916022241076_Purchase Order | M4: =HYPERLINK("https://zohosecurepay.in/books/brainlyticsolutionsprivatelim2/secure?CInvoiceID=2-4dcca1fc8e91862e3e870d6bff687189abcb7eac3da55dae8651e7b33d7aaf0b48c45cd22688ad4661593cafdbd828c494d9500e95014150f60683d11d31aab896416530a9013979 ", "94916022241076_Invoice") -> 94916022241076_Invoice
A5: 46222 | B5: IRA40152321 | C5: BB | D5: Bangalore-2-FV-FMCG-DC | E5: 311730376 | F5: in transit | G5: Bag Received at Facility | H5: Nagpur_Khapari_GW (Maharashtra) | I5: 46225 | J5: 46223.417 | K5: N/A | L5: =HYPERLINK("https://drive.google.com/file/d/1pifNxIqTcnPpqFVNn0SgZnMmGoNikbOm/view?usp=drivesdk", "311730376_Purchase Order") -> 311730376_Purchase Order | M5: =HYPERLINK("https://zohosecurepay.in/books/brainlyticsolutionsprivatelim2/secure?CInvoiceID=2-4dcca1fc8e91862e12a7e0ec60d8976e878563c6f71c2db53968dd6ca94b6d4bf5425d7b5e08f5ae61593cafdbd828c494d9500e9501415067bef4a100008d44b867a2aaaa2bd350 ", "311730376_Invoice") -> 311730376_Invoice
A6: 46222 | B6: IRA40157460 | C6: BB | D6: Hyderabad-FV-FMCG DC | E6: 311730508 | F6: in transit | G6: Vehicle Departed | H6: Nagpur_Khapari_GW (Maharashtra) | I6: 46224 | J6: 46223.417 | K6: N/A | L6: =HYPERLINK("https://drive.google.com/file/d/1fcRoI5IYGovFX0HQnwwvQYECWn-7YTSm/view?usp=drivesdk", "311730508_Purchase Order") -> 311730508_Purchase Order | M6: =HYPERLINK("https://zohosecurepay.in/books/brainlyticsolutionsprivatelim2/secure?CInvoiceID=2-4dcca1fc8e91862e6325f8082e3a7e03bee71f485f0081623968dd6ca94b6d4b6af55e293da3e81e61593cafdbd828c494d9500e9501415067bef4a100008d44db508abba390e017 ", "311730508_Invoice") -> 311730508_Invoice
A7: 46222 | B7: IRA40158890 | C7: BB | D7: Kundli-DC | E7: 311730643 | F7: in transit | G7: Vehicle delayed - Controllable | H7: Raipur_Mandhar_H (Chhattisgarh) | I7: 46224 | J7: 46223.417 | K7: N/A | L7: =HYPERLINK("https://drive.google.com/file/d/1vVEGABxOJcug36WnzE80oTEYdSW9xzKE/view?usp=drivesdk", "311730643_Purchase Order") -> 311730643_Purchase Order | M7: =HYPERLINK("https://zohosecurepay.in/books/brainlyticsolutionsprivatelim2/secure?CInvoiceID=2-4dcca1fc8e91862e4227b1d517e4230e0f02d28595d1aaee3968dd6ca94b6d4b30bfc1ca38b9ebb761593cafdbd828c494d9500e9501415067bef4a100008d444f6e4489412104e0 ", "311730643_Invoice") -> 311730643_Invoice
A8: 46222 | B8: IRA40160463 | C8: BB | D8: Noida-New-FC | E8: 311730809 | F8: in transit | G8: Vehicle delayed - Controllable | H8: Raipur_Mandhar_H (Chhattisgarh) | I8: 46224 | J8: 46223.417 | K8: N/A | L8: =HYPERLINK("https://drive.google.com/file/d/1mVDnsm99XIvGStQp1S253jVsD_QNCrE7/view?usp=drivesdk", "311730809_Purchase Order") -> 311730809_Purchase Order | M8: =HYPERLINK("https://zohosecurepay.in/books/brainlyticsolutionsprivatelim2/secure?CInvoiceID=2-4dcca1fc8e91862ed5d0eb58f7886bfbc1e6ee86e0427e783968dd6ca94b6d4ba68f0a334744647461593cafdbd828c494d9500e9501415067bef4a100008d44f8ffb428f776aba6 ", "311730809_Invoice") -> 311730809_Invoice
A9: 46222 | B9: IRA40153737 | C9: BB | D9: Bangalore-FMCG-DC | E9: 311730884 | F9: in transit | G9: Vehicle delayed - Controllable | H9: Nagpur_Khapari_GW (Maharashtra) | I9: 46224 | J9: 46223.417 | K9: N/A | L9: =HYPERLINK("https://drive.google.com/file/d/10NXd-bqxNAySsUnMuTZSJS_xHcFkaZDE/view?usp=drivesdk", "311730884_Purchase Order") -> 311730884_Purchase Order | M9: =HYPERLINK("https://zohosecurepay.in/books/brainlyticsolutionsprivatelim2/secure?CInvoiceID=2-4dcca1fc8e91862ebfedc2203beaa1d93325ee365e4eeb5375c0866b214e5db38a88325b888993ae61593cafdbd828c494d9500e95014150286c078548aa83871d1b7111177f33ba ", "311730884_Invoice") -> 311730884_Invoice
A10: 46222 | B10: 49990010052988 | C10: Blinkit | D10: Bengaluru B5 - Feeder Warehouse | E10: 311294667 | F10: out for delivery | G10: Out for delivery | H10: Bangalore_Kolathur_L (Karnataka) | I10: 46217 | J10: 46223.438 | K10: 273489751337 | L10: =HYPERLINK("https://drive.google.com/file/d/1gs35CaOkygf6NkUpVJFG9_cFPv8yEZRB/view?usp=drivesdk", "311294667_Purchase Order") -> 311294667_Purchase Order | M10: =HYPERLINK("https://zohosecurepay.in/books/brainlyticsolutionsprivatelim2/secure?CInvoiceID=2-4dcca1fc8e91862ed2e79d213ce32619bdcde6fca0dc464fec81987cba088e75e2a71ea58058f85161593cafdbd828c494d9500e9501415076d923ddcdbdecf9eb6905990a0804e4 ", "311294667_Invoice") -> 311294667_Invoice
A11: 46217 | B11: 6769710079618 | C11: Blinkit | D11: Hyderabad H3 - Feeder Warehouse | E11: 311635973 | F11: in transit | G11: NTD Updated | H11: Hyderabad_Temp6_L (Telangana) | I11: 46223 | J11: 46227.312 | K11: 586950115699 | L11: =HYPERLINK("https://drive.google.com/file/d/14ocXDYAuId1NXZzpAeiHhu0thSNNUDRK/view?usp=drivesdk", "311635973_Purchase Order") -> 311635973_Purchase Order | M11: =HYPERLINK("https://zohosecurepay.in/books/brainlyticsolutionsprivatelim2/secure?CInvoiceID=2-4dcca1fc8e91862e913a749a501c32b4cf4627ea18591ebdbd4f0f3133f17ac7e6d07f6d8f50cb9b61593cafdbd828c494d9500e9501415082197de3652ace3b3a9781b91a2faba2 ", "311635973_Invoice") -> 311635973_Invoice
A12: 46218 | B12: IRA40531971 | C12: BB | D12: Ahmedabad-FV-FMCG-DC | E12: 311729842 | F12: in transit | G12: Vehicle Departed | H12: Nagpur_Khapari_GW (Maharashtra) | I12: 46223 | J12: 46227.417 | K12: N/A | L12: =HYPERLINK("https://drive.google.com/file/d/1b3RbhN1E45lSPPJ7UAZt1iEclY08Weh2/view?usp=drivesdk", "311729842_Purchase Order") -> 311729842_Purchase Order | M12: =HYPERLINK("https://zohosecurepay.in/books/brainlyticsolutionsprivatelim2/secure?CInvoiceID=2-4dcca1fc8e91862ea636bcadcb585689790570621722c82c0910a0893613d9d3b89f84027cbaf9c961593cafdbd828c494d9500e9501415082197de3652ace3b9fbbff11fc94e247 ", "311729842_Invoice") -> 311729842_Invoice
A13: 46218 | B13: IRA40561811 | C13: BB | D13: Chennai-FMCG-DC | E13: 311821747 | F13: in transit | G13: weight captured | H13: Raipur_Mandhar_H (Chhattisgarh) | I13: 46227 | J13: 46227.417 | K13: N/A | L13: =HYPERLINK("https://drive.google.com/file/d/1pECNmev5HwWSZkMf6bZko7NqeJ5H9sK3/view?usp=drivesdk", "311821747_Purchase Order") -> 311821747_Purchase Order | M13: =HYPERLINK("https://zohosecurepay.in/books/brainlyticsolutionsprivatelim2/secure?CInvoiceID=2-4dcca1fc8e91862e86389686539bc8079af6c3ea2057fb530910a0893613d9d34a0b862a86494e2b61593cafdbd828c494d9500e9501415082197de3652ace3b489b7da3faa2fc0e ", "311821747_Invoice") -> 311821747_Invoice
A14: 46217 | B14: 49060410054875 | C14: Blinkit | D14: Faridabad Feeder | E14: 311602053 | F14: in transit | G14: NTD Updated | H14: Faridabad_Sector2_L (Haryana) | I14: 46223 | J14: 46228.354 | K14: 600529634596 | L14: =HYPERLINK("https://drive.google.com/file/d/1KrXUc_riRq5UyGZal1LRjDoz4gRjgiji/view?usp=drivesdk", "311602053_Purchase Order") -> 311602053_Purchase Order | M14: =HYPERLINK("https://zohosecurepay.in/books/brainlyticsolutionsprivatelim2/secure?CInvoiceID=2-4dcca1fc8e91862e09ed453b894714224987f88202627ab6bd4f0f3133f17ac7c6f0422b46af179261593cafdbd828c494d9500e9501415082197de3652ace3bdac6f1c5c6658ce3 ", "311602053_Invoice") -> 311602053_Invoice
A15: 46218 | B15: IRA40532915 | C15: BB | D15: Hyderabad-FV-FMCG DC | E15: 311729939 | F15: in transit | G15: Vehicle delayed - Controllable | H15: Nagpur_Khapari_GW (Maharashtra) | I15: 46224 | J15: 46228.417 | K15: N/A | L15: =HYPERLINK("https://drive.google.com/file/d/1pw_lcqT6mZ3bCQvhxm9wEBAyywu7n9Tn/view?usp=drivesdk", "311729939_Purchase Order") -> 311729939_Purchase Order | M15: =HYPERLINK("https://zohosecurepay.in/books/brainlyticsolutionsprivatelim2/secure?CInvoiceID=2-4dcca1fc8e91862e78f41e3c5d51025a3fccae5aa0dda5690910a0893613d9d3e94443fd6bff1e1b61593cafdbd828c494d9500e9501415082197de3652ace3bd80e87220c9691fc ", "311729939_Invoice") -> 311729939_Invoice
A16: 46218 | B16: IRA40547396 | C16: BB | D16: Bangalore-2-FV-FMCG-DC | E16: 311730303 | F16: in transit | G16: Vehicle delayed - Controllable | H16: Nagpur_Khapari_GW (Maharashtra) | I16: 46225 | J16: 46228.417 | K16: N/A | L16: =HYPERLINK("https://drive.google.com/file/d/1kLljdTPmZzfH8mU-e_7CBfyp9LVzHPNG/view?usp=drivesdk", "311730303_Purchase Order") -> 311730303_Purchase Order | M16: =HYPERLINK("https://zohosecurepay.in/books/brainlyticsolutionsprivatelim2/secure?CInvoiceID=2-4dcca1fc8e91862e9932e7f0570719a3d6dbcde52d9ed23e0910a0893613d9d38e7ff4c678102c2361593cafdbd828c494d9500e9501415082197de3652ace3b126d3a7c3440766d ", "311730303_Invoice") -> 311730303_Invoice
A17: 46216 | B17: 51388610006558 | C17: Blinkit | D17: Vijayawada - Feeder | E17: 311601815 | F17: in transit | G17: Vehicle Departed | H17: Hyderabad_Medchal_GW (Telangana) | I17: 46223 | J17: 46230.312 | K17: 201820324823 | L17: =HYPERLINK("https://drive.google.com/file/d/1MbEfPaR9zNIauLk97F_YhsmCzVrC_5T_/view?usp=drivesdk", "311601815_Purchase Order") -> 311601815_Purchase Order | M17: =HYPERLINK("https://zohosecurepay.in/books/brainlyticsolutionsprivatelim2/secure?CInvoiceID=2-4dcca1fc8e91862e913a749a501c32b40f1e266d653f0bccbd4f0f3133f17ac7955b500668403f3261593cafdbd828c494d9500e9501415082197de3652ace3b8fec77c05e7839e3 ", "311601815_Invoice") -> 311601815_Invoice
A18: 46216 | B18: 49990010057236 | C18: Blinkit | D18: Bengaluru B5 - Feeder Warehouse | E18: 311566305 | F18: in transit | G18: NTD Updated | H18: Bangalore_Kolathur_L (Karnataka) | I18: 46223 | J18: 46230.312 | K18: 277029740182 | L18: =HYPERLINK("https://drive.google.com/file/d/1cBghUbQrwz9lYF8-ozkyJ-IPzhWBK11p/view?usp=drivesdk", "311566305_Purchase Order") -> 311566305_Purchase Order | M18: =HYPERLINK("https://zohosecurepay.in/books/brainlyticsolutionsprivatelim2/secure?CInvoiceID=2-4dcca1fc8e91862e0e29bfdbb432183c9de0b67d1007a053bd4f0f3133f17ac7573d399de2b6ef8361593cafdbd828c494d9500e9501415082197de3652ace3b0c4b0416ff23ce78 ", "311566305_Invoice") -> 311566305_Invoice
A19: 46216 | B19: 8525210056210 | C19: Blinkit | D19: Chennai C5 - Feeder Warehouse | E19: 311566395 | F19: in transit | G19: Shipment Received at Facility | H19: Chennai_Nagalkeni_L (Tamil Nadu) | I19: 46223 | J19: 46230.312 | K19: 169676262182 | L19: =HYPERLINK("https://drive.google.com/file/d/1P0zZZdMSHtukFs1DilJGfnJxSs1cWbkr/view?usp=drivesdk", "311566395_Purchase Order") -> 311566395_Purchase Order | M19: =HYPERLINK("https://zohosecurepay.in/books/brainlyticsolutionsprivatelim2/secure?CInvoiceID=2-4dcca1fc8e91862eb009b444958fd677748bf17f76d05b1dbd4f0f3133f17ac7bfa65e7ec59626b461593cafdbd828c494d9500e9501415082197de3652ace3bd2cbe3d08c92c014 ", "311566395_Invoice") -> 311566395_Invoice
A20: 46216 | B20: 48287510043097 | C20: Blinkit | D20: Kolkata K6 Feeder | E20: 311635493 | F20: in transit | G20: NTD Updated | H20: Kolkata_Dankuni_GW (West Bengal) | I20: 46223 | J20: 46230.312 | K20: 739214297668 | L20: =HYPERLINK("https://drive.google.com/file/d/13zpg_y-Nh0X8rfzpKDAT6xi-sCSOMluO/view?usp=drivesdk", "311635493_Purchase Order") -> 311635493_Purchase Order | M20: =HYPERLINK("https://zohosecurepay.in/books/brainlyticsolutionsprivatelim2/secure?CInvoiceID=2-4dcca1fc8e91862e927a51cb038232c728a7f9da352f1751bd4f0f3133f17ac7821c0ca053dd09de61593cafdbd828c494d9500e9501415082197de3652ace3bd37cac4e982594b7 ", "311635493_Invoice") -> 311635493_Invoice
A21: 46216 | B21: 2273910087442 | C21: Blinkit | D21: Mumbai M10 - Feeder Warehouse | E21: 311635600 | F21: in transit | G21: NTD Updated | H21: Bhiwandi_Lonad_L (Maharashtra) | I21: 46223 | J21: 46230.312 | K21: 710042355251 | L21: =HYPERLINK("https://drive.google.com/file/d/1YFxAbdEjzYOuS8UjFpSzRgE0uG0d10Oz/view?usp=drivesdk", "311635600_Purchase Order") -> 311635600_Purchase Order | M21: =HYPERLINK("https://zohosecurepay.in/books/brainlyticsolutionsprivatelim2/secure?CInvoiceID=2-4dcca1fc8e91862edd2a6c92388e190aa7c00a8289a5ed7ebd4f0f3133f17ac76e9c6ec12452cc2a61593cafdbd828c494d9500e9501415082197de3652ace3bae67cab134db763d ", "311635600_Invoice") -> 311635600_Invoice
A22: 46217 | B22: 2738110058670 | C22: Blinkit | D22: Ahmedabad A2 - Feeder Warehouse | E22: 311635700 | F22: in transit | G22: NTD Updated | H22: Ahmedabad_Kanera_GW (Gujarat) | I22: 46223 | J22: 46230.312 | K22: 708897045925 | L22: =HYPERLINK("https://drive.google.com/file/d/1fNsaNM4TgM4_1MR97bOnWuFVO82i2ta-/view?usp=drivesdk", "311635700_Purchase Order") -> 311635700_Purchase Order | M22: =HYPERLINK("https://zohosecurepay.in/books/brainlyticsolutionsprivatelim2/secure?CInvoiceID=2-4dcca1fc8e91862e14e9d05f81d0c092c5ec0683b2923a06bd4f0f3133f17ac760b63cabccb87a6561593cafdbd828c494d9500e9501415082197de3652ace3b7024cfc327ee99b9 ", "311635700_Invoice") -> 311635700_Invoice
A23: 46217 | B23: 43886010055377 | C23: Blinkit | D23: Rajpura R2 - Feeder Warehouse | E23: 311666726 | F23: in transit | G23: Vehicle Departed | H23: Nagpur_Khapari_GW (Maharashtra) | I23: 46224 | J23: 46230.312 | K23: 251067187751 | L23: =HYPERLINK("https://drive.google.com/file/d/1HDAbcsepWD_omk7YYvPgqMZSFnpRmGkg/view?usp=drivesdk", "311666726_Purchase Order") -> 311666726_Purchase Order | M23: =HYPERLINK("https://zohosecurepay.in/books/brainlyticsolutionsprivatelim2/secure?CInvoiceID=2-4dcca1fc8e91862e376fc21cbc7560dc709408455e59bba90910a0893613d9d3b50fd93edd20790161593cafdbd828c494d9500e9501415082197de3652ace3b6f7d988d17d4d356 ", "311666726_Invoice") -> 311666726_Invoice
A24: 46216 | B24: 50033210022659 | C24: Blinkit | D24: Mumbai M12 - Feeder | E24: 311607585 | F24: in transit | G24: NTD Updated | H24: Bhiwandi_Lonad_L (Maharashtra) | I24: 46221 | J24: 46230.333 | K24: 439840630004 | L24: =HYPERLINK("https://drive.google.com/file/d/10UkDH32nPFpK7c4KXZdtrLLGLhE9jA-f/view?usp=drivesdk", "311607585_Purchase Order") -> 311607585_Purchase Order | M24: =HYPERLINK("https://zohosecurepay.in/books/brainlyticsolutionsprivatelim2/secure?CInvoiceID=2-4dcca1fc8e91862e8f523ee8ece542b331de972e15c03e52bd4f0f3133f17ac75d75d5fd3675579161593cafdbd828c494d9500e9501415082197de3652ace3b204a6853ce2a43d2 ", "311607585_Invoice") -> 311607585_Invoice
A25: 46217 | B25: 41315210033054 | C25: Blinkit | D25: Goa G2 - Feeder Warehouse | E25: 311674267 | F25: in transit | G25: Vehicle Departed | H25: Pune_Sudhwadi_GW (Maharashtra) | I25: 46223 | J25: 46230.354 | K25: 207294921861 | L25: =HYPERLINK("https://drive.google.com/file/d/1X-EAcK2D0oOus72CwRXNCT8lHSAC7A2G/view?usp=drivesdk", "311674267_Purchase Order") -> 311674267_Purchase Order | M25: =HYPERLINK("https://zohosecurepay.in/books/brainlyticsolutionsprivatelim2/secure?CInvoiceID=2-4dcca1fc8e91862e9932e7f0570719a39af6c3ea2057fb530910a0893613d9d356119ad8f02f8e0a61593cafdbd828c494d9500e9501415082197de3652ace3b589e42a571885b72 ", "311674267_Invoice") -> 311674267_Invoice
A26: 46217 | B26: 7165810027042 | C26: Blinkit | D26: Guwahati G1 - Feeder Warehouse | E26: 311607681 | F26: in transit | G26: Bag Received at Facility | H26: Kolkata_Dankuni_GW (West Bengal) | I26: 46224 | J26: 46230.354 | K26: 191151319435 | L26: =HYPERLINK("https://drive.google.com/file/d/1ybuIam-79snIyRt7PK2EgpXlOxcYbFcI/view?usp=drivesdk", "311607681_Purchase Order") -> 311607681_Purchase Order | M26: =HYPERLINK("https://zohosecurepay.in/books/brainlyticsolutionsprivatelim2/secure?CInvoiceID=2-4dcca1fc8e91862e91488d1794d233ce1ab4790927a7b6b3bd4f0f3133f17ac7e63534a92a7a088c61593cafdbd828c494d9500e9501415082197de3652ace3bdd1f2173266df490 ", "311607681_Invoice") -> 311607681_Invoice
A27: 46218 | B27: IRA40533793 | C27: BB | D27: Pune-FV- FMCG-DC | E27: 311796299 | F27: in transit | G27: weight captured | H27: Raipur_Mandhar_H (Chhattisgarh) | I27: 46224 | J27: 46230.417 | K27: N/A | L27: =HYPERLINK("https://drive.google.com/file/d/1mcAisw_mqSefupHd5UZoWVTqu7VI6Igm/view?usp=drivesdk", "311796299_Purchase Order") -> 311796299_Purchase Order | M27: =HYPERLINK("https://zohosecurepay.in/books/brainlyticsolutionsprivatelim2/secure?CInvoiceID=2-4dcca1fc8e91862e02f76b672199b560f3db284d230a59690910a0893613d9d3b7d342428ec2d64f61593cafdbd828c494d9500e9501415082197de3652ace3b256777c321ec4093 ", "311796299_Invoice") -> 311796299_Invoice
A28: 46220 | B28: 43886110055453 | C28: Blinkit | D28: Pune P3 - Feeder Warehouse | E28: 311789572 | F28: in transit | G28: weight captured | H28: Raipur_Mandhar_H (Chhattisgarh) | I28: 46224 | J28: 46233.271 | K28: 395547285424 | L28: =HYPERLINK("https://drive.google.com/file/d/1GledV5zba6Ea0LA-Ed8lMx3wTRFjjecP/view?usp=drivesdk", "311789572_Purchase Order") -> 311789572_Purchase Order | M28: =HYPERLINK("https://zohosecurepay.in/books/brainlyticsolutionsprivatelim2/secure?CInvoiceID=2-4dcca1fc8e91862e07158ff40d53f8849ba43dc9537e3af40910a0893613d9d3110c76f5a3f8949161593cafdbd828c494d9500e9501415082197de3652ace3b3c7a07a7cb935360 ", "311789572_Invoice") -> 311789572_Invoice
A29: 46220 | B29: 49990010059284 | C29: Blinkit | D29: Bengaluru B5 - Feeder Warehouse | E29: 311811343 | F29: in transit | G29: weight captured | H29: Raipur_Mandhar_H (Chhattisgarh) | I29: 46227 | J29: 46233.312 | K29: 429399714699 | L29: =HYPERLINK("https://drive.google.com/file/d/1f8O2XC-6IqgEReH6oc3lxcmaLmA8Ugjl/view?usp=drivesdk", "311811343_Purchase Order") -> 311811343_Purchase Order | M29: =HYPERLINK("https://zohosecurepay.in/books/brainlyticsolutionsprivatelim2/secure?CInvoiceID=2-4dcca1fc8e91862e86389686539bc807a038eaa461b5f67e0910a0893613d9d30cb8da59c57efc5661593cafdbd828c494d9500e9501415082197de3652ace3bb127c19a9e33243b ", "311811343_Invoice") -> 311811343_Invoice
A30: 46220 | B30: 48287510044733 | C30: Blinkit | D30: Kolkata K6 Feeder | E30: 311789178 | F30: in transit | G30: weight captured | H30: Raipur_Mandhar_H (Chhattisgarh) | I30: 46224 | J30: 46233.312 | K30: 769334277859 | L30: =HYPERLINK("https://drive.google.com/file/d/1A1zcSxg1cTsGJbYsAwVNa70hkz987FfI/view?usp=drivesdk", "311789178_Purchase Order") -> 311789178_Purchase Order | M30: =HYPERLINK("https://zohosecurepay.in/books/brainlyticsolutionsprivatelim2/secure?CInvoiceID=2-4dcca1fc8e91862e86389686539bc807bfbdfa783517e0d60910a0893613d9d38f70c6de7844088461593cafdbd828c494d9500e9501415082197de3652ace3b95ef53edb0d16aee ", "311789178_Invoice") -> 311789178_Invoice
A31: 46220 | B31: 2940310036378 | C31: Blinkit | D31: Lucknow L5 - Feeder Warehouse | E31: 311786786 | F31: in transit | G31: weight captured | H31: Raipur_Mandhar_H (Chhattisgarh) | I31: 46225 | J31: 46233.312 | K31: 748907742595 | L31: =HYPERLINK("https://drive.google.com/file/d/18NVxN49Wl26wvVfDx3kE-24dEPoqraUA/view?usp=drivesdk", "311786786_Purchase Order") -> 311786786_Purchase Order | M31: =HYPERLINK("https://zohosecurepay.in/books/brainlyticsolutionsprivatelim2/secure?CInvoiceID=2-4dcca1fc8e91862e4e2eba479a77028b1b7c27e56c7b9e090910a0893613d9d369098d61cbbb460f61593cafdbd828c494d9500e9501415082197de3652ace3bec0f5fc21a119536 ", "311786786_Invoice") -> 311786786_Invoice
A32: 46220 | B32: 8525210057435 | C32: Blinkit | D32: Chennai C5 - Feeder Warehouse | E32: 311786880 | F32: in transit | G32: weight captured | H32: Raipur_Mandhar_H (Chhattisgarh) | I32: 46226 | J32: 46233.312 | K32: 868906221155 | L32: =HYPERLINK("https://drive.google.com/file/d/1FmU7nPZK2LIeJ8VpU0jL9XmL2S57A4-N/view?usp=drivesdk", "311786880_Purchase Order") -> 311786880_Purchase Order | M32: =HYPERLINK("https://zohosecurepay.in/books/brainlyticsolutionsprivatelim2/secure?CInvoiceID=2-4dcca1fc8e91862e6de5dbba139bf184d54ce51b791d64630910a0893613d9d3648ef66f95ba2fcc61593cafdbd828c494d9500e9501415082197de3652ace3b36d6a93d59fe3642 ", "311786880_Invoice") -> 311786880_Invoice
A33: 46220 | B33: 1735810053165 | C33: Blinkit | D33: Lucknow L4 - Warehouse | E33: 311792596 | F33: in transit | G33: weight captured | H33: Raipur_Mandhar_H (Chhattisgarh) | I33: 46225 | J33: 46233.312 | K33: 343340630521 | L33: =HYPERLINK("https://drive.google.com/file/d/1F6R85HvyMaZrEdJ1toIgGQrTcXLTAncr/view?usp=drivesdk", "311792596_Purchase Order") -> 311792596_Purchase Order | M33: =HYPERLINK("https://zohosecurepay.in/books/brainlyticsolutionsprivatelim2/secure?CInvoiceID=2-4dcca1fc8e91862e6d2ddaa80509df980618f009474786dd0910a0893613d9d3d60a75142a9d6ad161593cafdbd828c494d9500e9501415082197de3652ace3bc00848c6ea187faf ", "311792596_Invoice") -> 311792596_Invoice
A34: 46220 | B34: 2576310056590 | C34: Blinkit | D34: Dasna D3 - Feeder Warehouse | E34: 311815201 | F34: in transit | G34: Bag Added To Trip | H34: Raipur_Mandhar_H (Chhattisgarh) | I34: 46226 | J34: 46233.479 | K34: 368246990504 | L34: =HYPERLINK("https://drive.google.com/file/d/1PyxxXQPG4aVrTbTo2AsrPg-7U6fEO46s/view?usp=drivesdk", "311815201_Purchase Order") -> 311815201_Purchase Order | M34: =HYPERLINK("https://zohosecurepay.in/books/brainlyticsolutionsprivatelim2/secure?CInvoiceID=2-4dcca1fc8e91862e8a63f365b7933d646fc19cf4054534550910a0893613d9d3568e4a6c1c5eec7461593cafdbd828c494d9500e9501415082197de3652ace3bd426dba8804ece0c ", "311815201_Invoice") -> 311815201_Invoice

Sheet Sheet6
A1: Status | B1: PO Number | F1: 46122 | G1: 6769710037985 | H1: Blinkit | I1: Hyderabad H3 - Feeder Warehouse | J1: 302627602 | K1: delivered | L1: Shipment Delivered | M1: Hyderabad_Temp6_L (Telangana) | N1: 46125 | O1: 46132.312 | P1: 945030195474 | Q1: =HYPERLINK("https://drive.google.com/file/d/17HWpy7LvhJ03IZaPvjqYAB6yRQxNRh6o/view?usp=drivesdk", "302627602_Purchase Order") -> 302627602_Purchase Order | R1: =HYPERLINK("https://zohosecurepay.in/books/brainlyticsolutionsprivatelim2/secure?CInvoiceID=2-4dcca1fc8e91862eb3395e1b54b2e0d59c02a7500dd23fe6a64403c286be8a0e1793ef4a6595a22961593cafdbd828c494d9500e95014150086d0182747ec7f033861748a7bfa36d ", "302627602_Invoice") -> 302627602_Invoice
A2: New | B2: 1736010016145 | C2: =VLOOKUP(B2,'Action Required'!B:B,1,0) -> #N/A | F2: 46159 | G2: 6769710053040 | H2: Blinkit | I2: Hyderabad H3 - Feeder Warehouse | J2: 94916022218876 | K2: delivered | L2: Delivered | M2: HYD/PC1, Hyderabad, TELANGANA | N2: N/A | O2: 46170.312 | P2: 633160169381 | Q2: =HYPERLINK("https://drive.google.com/file/d/1q5lZ_mAB3XemhFIqsfHVewMOi4Dkckh3/view?usp=drivesdk", "94916022218876_Purchase Order") -> 94916022218876_Purchase Order | R2: =HYPERLINK("https://zohosecurepay.in/books/brainlyticsolutionsprivatelim2/secure?CInvoiceID=2-4dcca1fc8e91862e9a865945166178a5628a222d473b3e774ab6cd08af2851ca768d046eb57d095461593cafdbd828c494d9500e95014150471054b8eff9ec4749e723c63de499af ", "94916022218876_Invoice") -> 94916022218876_Invoice
A3: New | B3: 1736010016145 | C3: =VLOOKUP(B3,'Action Required'!B:B,1,0) -> #N/A
A4: New | B4: 2273910018522 | C4: =VLOOKUP(B4,'Action Required'!B:B,1,0) -> #N/A
A5: New | B5: 2273910018522 | C5: =VLOOKUP(B5,'Action Required'!B:B,1,0) -> #N/A
A6: New | B6: 5407610002820 | C6: =VLOOKUP(B6,'Action Required'!B:B,1,0) -> #N/A
A7: New | B7: 5407610002820 | C7: =VLOOKUP(B7,'Action Required'!B:B,1,0) -> #N/A
A8: New | B8: 3292010003688 | C8: =VLOOKUP(B8,'Action Required'!B:B,1,0) -> #N/A
A9: New | B9: IRA31602790 | C9: =VLOOKUP(B9,'Action Required'!B:B,1,0) -> #N/A
A10: New | B10: IRA31602790 | C10: =VLOOKUP(B10,'Action Required'!B:B,1,0) -> #N/A
A11: New | B11: IRA31602790 | C11: =VLOOKUP(B11,'Action Required'!B:B,1,0) -> #N/A
A12: New | B12: IRA31602790 | C12: =VLOOKUP(B12,'Action Required'!B:B,1,0) -> #N/A
A13: New | B13: IRA31602790 | C13: =VLOOKUP(B13,'Action Required'!B:B,1,0) -> #N/A
A14: New | B14: IRA31602790 | C14: =VLOOKUP(B14,'Action Required'!B:B,1,0) -> #N/A
A15: New | B15: IRA31602790 | C15: =VLOOKUP(B15,'Action Required'!B:B,1,0) -> #N/A
A16: New | B16: P3048054 | C16: =VLOOKUP(B16,'Action Required'!B:B,1,0) -> #N/A
A17: New | B17: P3048054 | C17: =VLOOKUP(B17,'Action Required'!B:B,1,0) -> #N/A
A18: New | B18: P3048054 | C18: =VLOOKUP(B18,'Action Required'!B:B,1,0) -> #N/A
A19: New | B19: 2896610003346 | C19: =VLOOKUP(B19,'Action Required'!B:B,1,0) -> #N/A
A20: New | B20: 2867410015545 | C20: =VLOOKUP(B20,'Action Required'!B:B,1,0) -> #N/A
A21: New | B21: 1736010016741 | C21: =VLOOKUP(B21,'Action Required'!B:B,1,0) -> #N/A
A22: New | B22: 2011710013630 | C22: =VLOOKUP(B22,'Action Required'!B:B,1,0) -> #N/A
A23: New | B23: 2011710013630 | C23: =VLOOKUP(B23,'Action Required'!B:B,1,0) -> #N/A
A24: New | B24: 2867410016130 | C24: =VLOOKUP(B24,'Action Required'!B:B,1,0) -> #N/A
A25: New | B25: 2867410016130 | C25: =VLOOKUP(B25,'Action Required'!B:B,1,0) -> #N/A
A26: New | B26: 2011710014091 | C26: =VLOOKUP(B26,'Action Required'!B:B,1,0) -> #N/A
A27: New | B27: 2011710014091 | C27: =VLOOKUP(B27,'Action Required'!B:B,1,0) -> #N/A
A28: New | B28: 2273910019524 | C28: =VLOOKUP(B28,'Action Required'!B:B,1,0) -> #N/A
A29: New | B29: 1736010017398 | C29: =VLOOKUP(B29,'Action Required'!B:B,1,0) -> #N/A
A30: New | B30: 1736010017398 | C30: =VLOOKUP(B30,'Action Required'!B:B,1,0) -> #N/A
... A33: New | B33: 2135610012376 | C33: =VLOOKUP(B33,'Action Required'!B:B,1,0) -> #N/A
A34: New | B34: P3116052 | C34: =VLOOKUP(B34,'Action Required'!B:B,1,0) -> #N/A
A35: New | B35: P3116052 | C35: =VLOOKUP(B35,'Action Required'!B:B,1,0) -> #N/A
A36: New | B36: P3116052 | C36: =VLOOKUP(B36,'Action Required'!B:B,1,0) -> #N/A
A37: New | B37: P3116052 | C37: =VLOOKUP(B37,'Action Required'!B:B,1,0) -> #N/A
A38: New | B38: P3116110 | C38: =VLOOKUP(B38,'Action Required'!B:B,1,0) -> #N/A
A39: New | B39: P3116110 | C39: =VLOOKUP(B39,'Action Required'!B:B,1,0) -> #N/A
A40: New | B40: P3116110 | C40: =VLOOKUP(B40,'Action Required'!B:B,1,0) -> #N/A
A41: New | B41: P3116110 | C41: =VLOOKUP(B41,'Action Required'!B:B,1,0) -> #N/A
A42: New | B42: P3116110 | C42: =VLOOKUP(B42,'Action Required'!B:B,1,0) -> #N/A
...

Sheet POD Uploads
A1: Timestamp | B1: AWB | C1: POD URL
A2: 45806.551 | B2: 281460328 | C2: https://drive.google.com/file/d/1PY6b2cl1ZkOR8yr5TfgWF-wfM3SWTAes/view?usp=drivesdk
A3: 45807.56 | B3: 281317114 | C3: https://drive.google.com/file/d/1dUqfFgB7Tmux_KynrEiJsu7tNDUkAtaG/view?usp=drivesdk
A4: 45807.56 | B4: 281317114 | C4: https://drive.google.com/file/d/1qYhlwDjPoS-GS2I7b_IariOdw3Kt1Djc/view?usp=drivesdk
A5: 45807.56 | B5: 281500755 | C5: https://drive.google.com/file/d/1WMUb4WGVgOiIUh_JLYfg_yF-qPvodBqX/view?usp=drivesdk
A6: 45812.506 | B6: 281703700 | C6: https://drive.google.com/file/d/1QATPS5cSAa9zTr65o8xYAJZTbbFbrJfY/view?usp=drivesdk
A7: 45813.478 | B7: 281603724 | C7: https://drive.google.com/file/d/1ewjukwotlbFO9Sbzor4ls5Uis_rVx2um/view?usp=drivesdk
A8: 45820.541 | B8: 281751654 | C8: https://drive.google.com/file/d/1CAuGe6IkJte5_rWCEd8IrCd6cEkaKlnl/view?usp=drivesdk
A9: 45820.541 | B9: 282091463 | C9: https://drive.google.com/file/d/1utasJ_zyEAD_-UgYBEhZyVRxpMM0pFDy/view?usp=drivesdk
A10: 45820.541 | B10: 281721038 | C10: https://drive.google.com/file/d/16sSMx1_pw6jMSZEzvzFn73OoCynXoy2X/view?usp=drivesdk
A11: 45820.541 | B11: 281858154 | C11: https://drive.google.com/file/d/13uVkjGRGCplUbspK3PhpcavhjaM7SztQ/view?usp=drivesdk
A12: 45820.541 | B12: 281972530 | C12: https://drive.google.com/file/d/1_s1PFpR38m6FZUS6R1uv0UjSeD2mbUEZ/view?usp=drivesdk
A13: 45821.642 | B13: 281862509 | C13: https://drive.google.com/file/d/1bwU9w2829bd6TAa4wvkKqqdnGSBMoKyI/view?usp=drivesdk
... A70: 45866.515 | B70: 283291476 | C70: https://drive.google.com/file/d/1mliwbg4kq3ioMbDjvd9m9Fu4NAL0GAng/view?usp=drivesdk
A71: 45866.515 | B71: SHIPMENTS_1753436048 | C71: https://drive.google.com/file/d/1S7AGmuPZbsNMienEhzR8z5IVNXbrqqtd/view?usp=drivesdk
A72: 45866.515 | B72: 283076461 | C72: https://drive.google.com/file/d/1h8jfCinl7-SfKSgk7lKf4cHXyIjXI7am/view?usp=drivesdk
A73: 45866.516 | B73: 283540328 | C73: https://drive.google.com/file/d/19poGNHVRpwM1f9ZurXBjsn00MRWad0Mz/view?usp=drivesdk
A74: 45866.516 | B74: 282786907 | C74: https://drive.google.com/file/d/1gs1gb1MzHxRqw8sajNKE8apxUjaigYgh/view?usp=drivesdk
A75: 45866.516 | B75: 283100908 | C75: https://drive.google.com/file/d/1oZ3Sbn6YZq7U8iXBBdask7LXrsax3Sp-/view?usp=drivesdk
A76: 45866.516 | B76: 283306190 | C76: https://drive.google.com/file/d/1Ptd8KkC6BBgpeenHsXO6o_ZRMMwDq0L_/view?usp=drivesdk
A77: 45866.516 | B77: SHIPMENTS_1753436048 | C77: https://drive.google.com/file/d/1dUL0H9pkTOQ7QaV_ATQjUhBwKyl5P2Qz/view?usp=drivesdk
A78: 45866.516 | B78: 283345998 | C78: https://drive.google.com/file/d/1KXBINVBRjmDb4asp9RIyb1cNkhs5fXPS/view?usp=drivesdk
A79: 45866.516 | B79: 283291476 | C79: https://drive.google.com/file/d/1WQlC_hmSCIOTgagbvOX5ga1-mJnzY_nm/view?usp=drivesdk
A80: 45866.516 | B80: 283291486 | C80: https://drive.google.com/file/d/1OzHvgAUYxqB2V4qTGFsVCIMf7g4nXFJb/view?usp=drivesdk
A81: 45866.516 | B81: 283312945 | C81: https://drive.google.com/file/d/1_PmEwbHSojr8wbjklAhIGbmAw2HZpfI8/view?usp=drivesdk
A82: 45866.516 | B82: 283076461 | C82: https://drive.google.com/file/d/1-kTddSUfV-ucddgr9_ketlmOFuE2QWV7/view?usp=drivesdk
A83: 45866.516 | B83: 283304830 | C83: https://drive.google.com/file/d/1jmdKihAYtPz6iyf6HSKnKLNhH0lFLEL3/view?usp=drivesdk
A84: 45866.516 | B84: 283450022 | C84: https://drive.google.com/file/d/1QgfiaGg-JFRalF5wy7e7GI0uFUMIrfDX/view?usp=drivesdk
A85: 45873.552 | B85: 283540219 | C85: https://drive.google.com/file/d/1TYcjTTrMZDT-16fA2PBJwo034WqjgPRY/view?usp=drivesdk
A86: 45873.552 | B86: 283728252 | C86: https://drive.google.com/file/d/1AujDi6-tEZq9XXftSxDu8FXArGcXcPIZ/view?usp=drivesdk
A87: 45873.552 | B87: 283540262 | C87: https://drive.google.com/file/d/1fs7MB3kRe23L8Mdh69_wwArVlbEYDjS3/view?usp=drivesdk
A88: 45873.552 | B88: 283845015 | C88: https://drive.google.com/file/d/1JYT909lHAcRkSZsrrTbK_yfFwo6RJMRS/view?usp=drivesdk
A89: 45873.552 | B89: 283735315 | C89: https://drive.google.com/file/d/1NMKasZg6U80rRrKpt0sFT80pm2Donv09/view?usp=drivesdk
... A223: 45988.705 | B223: 293134440 | C223: https://drive.google.com/file/d/1rAdu3X7EdIxu66cqk3tF8tASiN7Jr6iZ/view?usp=drivesdk
A224: 45988.705 | B224: 5C98C766-89D2-42EE-9B64-8A26E1712068 | C224: https://drive.google.com/file/d/1ZSvDnBMxjmbOJWHfByD6VcXScbsJQEEQ/view?usp=drivesdk
A225: 45988.705 | B225: 291658594 | C225: https://drive.google.com/file/d/1CXo11Gzx8alzPq9nyt2l7hQ6bdSLlMwX/view?usp=drivesdk
A226: 45988.705 | B226: 292664533 | C226: https://drive.google.com/file/d/1gPL00z9iIb16CtFeLnxMPo2mqVgWTFWL/view?usp=drivesdk
A227: 45988.705 | B227: 291917727 | C227: https://drive.google.com/file/d/10Pv_pBvwvotxtpzcbNoWGedmh5gFKIf2/view?usp=drivesdk
A228: 45988.705 | B228: 291304916 | C228: https://drive.google.com/file/d/1zSQR2I8AYSYDLUGUlZqQhQPQdY1ciKgL/view?usp=drivesdk
A229: 45988.705 | B229: 292908164 | C229: https://drive.google.com/file/d/1ws13uv6ArZi0VB0F_uFS-3hFY6_8RbqL/view?usp=drivesdk
...
